#Expyriment 1.0.0 (Python 3.10.5), .xpe-file, coding: UTF-8
#date: Sat Sep 20 2025 23:37:15
#sha1: 22405e
#modules: 
#display: size=(800, 600), window_mode=True, opengl=2
#os: uname_result(system='Linux', node='eoghan-Precision-7530', release='6.8.0-79-generic', version='#79-Ubuntu SMP PREEMPT_DYNAMIC Tue Aug 12 14:42:46 UTC 2025', machine='x86_64')
Time,Type,Event,Value,Detail,Detail2
1986,design,log,
#design: #exp: Launching
#design: block_cnt,block_id,trial_cnt,trial_id
1986,design,logged,
1986,Experiment,started
1986,stderr,received,'Traceback (most recent call last):'
1986,stderr,received,'  File "/home/eoghan/Documents/cog_sup/experimental_app/PPE/Week-2/Exercises/launching.py", line 34, in <module>'
1986,stderr,received,'    exp.clock.init_time()'
1986,stderr,received,"TypeError: 'float' object is not callable"
